Workbook

Sheet USDA_LOGS
A1: Timestamp | B1: Ingrediente_original | C1: Tradução_EN | D1: fdcId | E1: Description | F1: Nutrientes_JSON | G1: Status
A2: 2025-11-17T15:29:16.592Z | B2: Extrato de suco de laranja | C2: extrato de suco de laranja | D2: 2710605 | E2: Atole de avena | F2: {"energy":83,"carbs":15.46,"protein":1.74,"fat":1.58,"saturatedFat":0.835,"transFat":0,"fiber":0.2,"sodium":18} | G2: ok
A3: 2025-11-17T15:46:37.593Z | B3: orange | C3: orange | D3: 1864680 | E3: ORANGE | F3: {"energy":381,"carbs":90.5,"protein":4.76,"fat":0,"saturatedFat":0,"transFat":0,"fiber":0,"sodium":381} | G3: ok
A4: 2025-11-17T16:15:04.955Z | B4: orange | C4: orange | D4: 1864680 | E4: ORANGE | F4: {"energy":381,"carbs":90.5,"protein":4.76,"fat":0,"saturatedFat":0,"transFat":0,"fiber":0,"sodium":381} | G4: cache
A5: 2025-11-17T16:15:06.594Z | B5: laranja | C5: orange | D5: 1864680 | E5: ORANGE | F5: {"energy":381,"carbs":90.5,"protein":4.76,"fat":0,"saturatedFat":0,"transFat":0,"fiber":0,"sodium":381} | G5: ok
A6: 2025-11-17T16:15:29.456Z | B6: orange | C6: orange | D6: 1864680 | E6: ORANGE | F6: {"energy":381,"carbs":90.5,"protein":4.76,"fat":0,"saturatedFat":0,"transFat":0,"fiber":0,"sodium":381} | G6: cache
A7: 2025-11-17T16:15:31.318Z | B7: morango | C7: strawberry | D7: 2388788 | E7: STRAWBERRY | F7: {"energy":50,"carbs":113,"protein":3.33,"fat":0,"saturatedFat":0,"transFat":0,"fiber":10,"sodium":67} | G7: ok
A8: 2025-11-17T16:26:25.965Z | B8: strawberries, raw | C8: strawberries, raw | D8: 2709283 | E8: Strawberries, raw | F8: {"energy":36,"carbs":7.96,"protein":0.64,"fat":0.22,"saturatedFat":0,"transFat":0,"fiber":1.8,"sodium":0} | G8: ok
A9: 2025-11-17T16:57:54.152Z | B9: morango | C9: strawberry | D9: 2388788 | E9: STRAWBERRY | F9: {"energy":50,"carbs":113,"protein":3.33,"fat":0,"saturatedFat":0,"transFat":0,"fiber":10,"sodium":67} | G9: cache
A10: 2025-11-17T16:58:40.353Z | B10: morango | C10: strawberry | D10: 2388788 | E10: STRAWBERRY | F10: {"energy":50,"carbs":113,"protein":3.33,"fat":0,"saturatedFat":0,"transFat":0,"fiber":10,"sodium":67} | G10: cache
A11: 2025-11-17T17:00:08.789Z | B11: morango | C11: strawberry | D11: 2388788 | E11: STRAWBERRY | F11: {"energy":50,"carbs":113,"protein":3.33,"fat":0,"saturatedFat":0,"transFat":0,"fiber":10,"sodium":67} | G11: cache
A12: 2025-11-17T17:00:10.404Z | B12: morango, raw | C12: morango, raw | D12: 2709215 | E12: Apple, raw | F12: {"energy":61,"carbs":14.8,"protein":0.17,"fat":0.15,"saturatedFat":0.028,"transFat":0,"fiber":2.1,"sodium":0} | G12: ok
A13: 2025-11-17T17:00:32.009Z | B13: morango | C13: strawberry | D13: 2388788 | E13: STRAWBERRY | F13: {"energy":50,"carbs":113,"protein":3.33,"fat":0,"saturatedFat":0,"transFat":0,"fiber":10,"sodium":67} | G13: cache
... A23: 2025-11-17T19:34:13.108Z | B23: Oranges, raw | C23: oranges, raw | D23: 746771 | E23: Oranges, raw, navels | F23: {"energy":47,"carbs":11.8,"protein":0.91,"fat":0.15,"saturatedFat":0,"transFat":0,"fiber":2,"sodium":9} | G23: cache
A24: 2025-11-17T19:34:14.495Z | B24: TOTAL_RECEITA | C24: total_receita | I24: {"message":"no_results"} | J24: no_result
A25: 2025-11-17T19:48:04.303Z | B25: Oranges, raw | C25: oranges, raw | D25: 746771 | E25: Oranges, raw, navels | F25: {"energy":47,"carbs":11.8,"protein":0.91,"fat":0.15,"saturatedFat":0,"transFat":0,"fiber":2,"sodium":9} | G25: cache
A26: 2025-11-17T19:48:05.854Z | B26: aplle | C26: aplle | D26: 1886250 | E26: SNACKS, CINNAMON APLLE | F26: {"energy":400,"carbs":90,"added_sugars":0,"protein":0,"fat":0,"saturatedFat":0,"transFat":0,"monounsaturated":0,"polyunsaturated":0,"omega6":0,"omega3":0,"cholesterol":0,"fiber":10} | G26: ok
A27: 2025-11-17T19:48:07.411Z | B27: TOTAL_RECEITA | C27: total_receita | I27: {"message":"no_results"} | J27: no_result
A28: 2025-11-17T19:48:28.745Z | B28: Oranges, raw | C28: oranges, raw | D28: 746771 | E28: Oranges, raw, navels | F28: {"energy":47,"carbs":11.8,"protein":0.91,"fat":0.15,"saturatedFat":0,"transFat":0,"fiber":2,"sodium":9} | G28: cache
A29: 2025-11-17T19:48:30.614Z | B29: aplle, raw | C29: aplle, raw | D29: 2709215 | E29: Apple, raw | F29: {"energy":61,"carbs":14.8,"added_sugars":0,"protein":0.17,"fat":0.15,"saturatedFat":0.03,"transFat":0,"monounsaturated":0.01,"polyunsaturated":0.05,"omega6":0,"omega3":0,"cholesterol":0,"fiber":2.1} | G29: ok
A30: 2025-11-17T19:48:32.521Z | B30: TOTAL_RECEITA | C30: total_receita | I30: {"message":"no_results"} | J30: no_result
A31: 2025-11-17T20:25:55.744Z | B31: Oranges, raw | C31: oranges, raw | D31: 746771 | E31: Oranges, raw, navels | F31: {"energy":47,"carbs":11.8,"protein":0.91,"fat":0.15,"saturatedFat":0,"transFat":0,"fiber":2,"sodium":9} | G31: cache
A32: 2025-11-17T20:25:56.600Z | B32: aplle, raw | C32: aplle, raw | D32: 2709215 | E32: Apple, raw | F32: {"energy":61,"carbs":14.8,"added_sugars":0,"protein":0.17,"fat":0.15,"saturatedFat":0.03,"transFat":0,"monounsaturated":0.01,"polyunsaturated":0.05,"omega6":0,"omega3":0,"cholesterol":0,"fiber":2.1} | G32: cache
A33: 2025-11-17T20:25:59.429Z | B33: SUco laranja integral | C33: suco laranja integral | D33: 2615812 | E33: INTEGRAL CRACKERS | F33: {"energy":452,"carbs":61.3,"added_sugars":0,"protein":9.68,"fat":16.1,"saturatedFat":8.06,"transFat":0,"monounsaturated":6.45,"polyunsaturated":0,"omega6":0,"omega3":0,"cholesterol":0,"fiber":3.2} | G33: ok
A34: 2025-11-18T23:09:33.404Z | B34: Oranges, raw | C34: oranges, raw | D34: 746771 | E34: Oranges, raw, navels | F34: {"energy":47,"carbs":11.8,"protein":0.91,"fat":0.15,"saturatedFat":0,"transFat":0,"fiber":2,"sodium":9} | G34: cache
A35: 2025-11-18T23:27:13.087Z | B35: Oranges, raw | C35: oranges, raw | D35: 746771 | E35: Oranges, raw, navels | F35: {"energy":47,"carbs":11.8,"protein":0.91,"fat":0.15,"saturatedFat":0,"transFat":0,"fiber":2,"sodium":9} | G35: cache
A36: 2025-11-18T23:28:03.148Z | B36: Oranges, raw | C36: oranges, raw | D36: 746771 | E36: Oranges, raw, navels | F36: {"energy":47,"carbs":11.8,"protein":0.91,"fat":0.15,"saturatedFat":0,"transFat":0,"fiber":2,"sodium":9} | G36: cache
A37: 2025-11-18T23:28:20.356Z | B37: Oranges, raw | C37: oranges, raw | D37: 746771 | E37: Oranges, raw, navels | F37: {"energy":47,"carbs":11.8,"protein":0.91,"fat":0.15,"saturatedFat":0,"transFat":0,"fiber":2,"sodium":9} | G37: cache
A38: 2025-11-19T00:37:42.963Z | B38: Oranges, raw | C38: oranges, raw | D38: 746771 | E38: Oranges, raw, navels | F38: {"energy":47,"carbs":11.8,"protein":0.91,"fat":0.15,"saturatedFat":0,"transFat":0,"fiber":2,"sodium":9} | G38: cache
A39: 2025-11-19T00:37:44.902Z | B39: APPLE, RAW | C39: apple, raw | D39: 2709215 | E39: Apple, raw | F39: {"energy":61,"carbs":14.8,"total_sugars":12.08,"added_sugars":0,"protein":0.17,"fat":0.15,"saturatedFat":0.03,"transFat":0,"monounsaturated":0.01,"polyunsaturated":0.05,"omega6":0,"omega3":0,"cholesterol":0,"fiber":2.1} | G39: ok
A40: 2025-11-20T03:35:51.617Z | B40: maça, crua | C40: maca, crua | D40: 2412673 | E40: MACA FLOUR, MACA | F40: {"energy":310,"carbs":70,"total_sugars":0,"added_sugars":0,"protein":10,"fat":0,"saturatedFat":0,"transFat":0,"monounsaturated":0,"polyunsaturated":0,"omega6":0,"omega3":0,"cholesterol":0,"fiber":20} | G40: ok
A41: 2025-11-20T03:36:08.641Z | B41: maça | C41: apple | D41: 2709215 | E41: Apple, raw | F41: {"energy":61,"carbs":14.8,"total_sugars":12.08,"added_sugars":0,"protein":0.17,"fat":0.15,"saturatedFat":0.03,"transFat":0,"monounsaturated":0.01,"polyunsaturated":0.05,"omega6":0,"omega3":0,"cholesterol":0,"fiber":2.1} | G41: ok
A42: 2025-11-20T03:37:54.096Z | B42: blackberries, raw | C42: blackberries, raw | D42: 2709273 | E42: Blackberries, raw | F42: {"energy":43,"carbs":9.61,"total_sugars":4.88,"added_sugars":0,"protein":1.39,"fat":0.49,"saturatedFat":0.01,"transFat":0,"monounsaturated":0.05,"polyunsaturated":0.28,"omega6":0,"omega3":0,"cholesterol":0,"fiber":5.3} | G42: ok
... A49: 2025-11-20T03:57:23.766Z | B49: aplle | C49: aplle | D49: 1886250 | E49: SNACKS, CINNAMON APLLE | F49: {"energy":400,"carbs":90,"added_sugars":0,"protein":0,"fat":0,"saturatedFat":0,"transFat":0,"monounsaturated":0,"polyunsaturated":0,"omega6":0,"omega3":0,"cholesterol":0,"fiber":10} | G49: cache

Sheet TABELA_TECNICA
A1: Ingrediente | B1: Energia_kcal_per100g | C1: Carboidratos_g | D1: Acucares_totais_g | E1: Acucares_adicionados_g | F1: Proteinas_g | G1: Gorduras_totais_g | H1: Gorduras_saturadas_g | I1: Gorduras_trans_g | J1: Gorduras_mono_g | K1: Gorduras_poly_g | L1: Omega6_g | M1: Omega3_g | N1: Colesterol_mg | O1: Fibra_g | P1: Sodio_mg | Q1: Description_USDA | R1: fdcId
A2: blackberries, raw | B2: 43 | C2: 9.61 | D2: 4.88 | E2: 0 | F2: 1.39 | G2: 0.49 | H2: 0.01 | I2: 0 | J2: 0.05 | K2: 0.28 | L2: 0 | M2: 0 | N2: 0 | O2: 5.3 | P2: 1 | Q2: Blackberries, raw | R2: 2709273
A3: açúcar cristal | C3: 99.5 | D3: 99.5 | E3: 99.5 | F3: 0.3 | P3: 12
A4: Suco de limão | C4: 7.6 | D4: 0 | E4: 0 | F4: 0.6 | G4: 0.1 | P4: 0

Sheet CALCULO_NUTRICIONAL
A1: Ingrediente | B1: Quantidade_g_ml | C1: Energia_kcal_per100g | D1: Carboidratos_g | E1: Acucares_totais_g | F1: Acucares_adicionados_g | G1: Proteinas_g | H1: Gorduras_totais_g | I1: Gorduras_saturadas_g | J1: Gorduras_trans_g | K1: Gorduras_mono_g | L1: Gorduras_poly_g | M1: Omega6_g | N1: Omega3_g | O1: Colesterol_mg | P1: Fibra_g | Q1: Sodio_mg
A2: =TABELA_TECNICA!A2 -> blackberries, raw | B2: 1000 | C2: =IFERROR((B2/100)*VLOOKUP($A2,TABELA_TECNICA!$A:$R,2,FALSE),"") -> 430 | D2: =IFERROR((B2/100)*VLOOKUP($A2,TABELA_TECNICA!$A:$R,3,FALSE),"") -> 96.1 | E2: =IFERROR((B2/100)*VLOOKUP($A2,TABELA_TECNICA!$A:$R,4,FALSE),"") -> 48.8 | F2: =IFERROR((B2/100)*VLOOKUP($A2,TABELA_TECNICA!$A:$R,5,FALSE),"") -> 0 | G2: =IFERROR((B2/100)*VLOOKUP($A2,TABELA_TECNICA!$A:$R,6,FALSE),"") -> 13.9 | H2: =IFERROR((B2/100)*VLOOKUP($A2,TABELA_TECNICA!$A:$R,7,FALSE),"") -> 4.9 | I2: =IFERROR((B2/100)*VLOOKUP($A2,TABELA_TECNICA!$A:$R,8,FALSE),"") -> 0.1 | J2: =IFERROR((B2/100)*VLOOKUP($A2,TABELA_TECNICA!$A:$R,9,FALSE),"") -> 0 | K2: =IFERROR((B2/100)*VLOOKUP($A2,TABELA_TECNICA!$A:$R,10,FALSE),"") -> 0.5 | L2: =IFERROR((B2/100)*VLOOKUP($A2,TABELA_TECNICA!$A:$R,11,FALSE),"") -> 2.8 | M2: =IFERROR((B2/100)*VLOOKUP($A2,TABELA_TECNICA!$A:$R,12,FALSE),"") -> 0 | N2: =IFERROR((B2/100)*VLOOKUP($A2,TABELA_TECNICA!$A:$R,13,FALSE),"") -> 0 | O2: =IFERROR((B2/100)*VLOOKUP($A2,TABELA_TECNICA!$A:$R,14,FALSE),"") -> 0 | P2: =IFERROR((B2/100)*VLOOKUP($A2,TABELA_TECNICA!$A:$R,15,FALSE),"") -> 53 | Q2: =IFERROR((B2/100)*VLOOKUP($A2,TABELA_TECNICA!$A:$R,16,FALSE),"") -> 10
A3: =TABELA_TECNICA!A3 -> açúcar cristal | B3: 1000 | C3: =IFERROR((B3/100)*VLOOKUP($A3,TABELA_TECNICA!$A:$R,2,FALSE),"") -> 0 | D3: =IFERROR((B3/100)*VLOOKUP($A3,TABELA_TECNICA!$A:$R,3,FALSE),"") -> 995 | E3: =IFERROR((B3/100)*VLOOKUP($A3,TABELA_TECNICA!$A:$R,4,FALSE),"") -> 995 | F3: =IFERROR((B3/100)*VLOOKUP($A3,TABELA_TECNICA!$A:$R,5,FALSE),"") -> 995 | G3: =IFERROR((B3/100)*VLOOKUP($A3,TABELA_TECNICA!$A:$R,6,FALSE),"") -> 3 | H3: =IFERROR((B3/100)*VLOOKUP($A3,TABELA_TECNICA!$A:$R,7,FALSE),"") -> 0 | I3: =IFERROR((B3/100)*VLOOKUP($A3,TABELA_TECNICA!$A:$R,8,FALSE),"") -> 0 | J3: =IFERROR((B3/100)*VLOOKUP($A3,TABELA_TECNICA!$A:$R,9,FALSE),"") -> 0 | K3: =IFERROR((B3/100)*VLOOKUP($A3,TABELA_TECNICA!$A:$R,10,FALSE),"") -> 0 | L3: =IFERROR((B3/100)*VLOOKUP($A3,TABELA_TECNICA!$A:$R,11,FALSE),"") -> 0 | M3: =IFERROR((B3/100)*VLOOKUP($A3,TABELA_TECNICA!$A:$R,12,FALSE),"") -> 0 | N3: =IFERROR((B3/100)*VLOOKUP($A3,TABELA_TECNICA!$A:$R,13,FALSE),"") -> 0 | O3: =IFERROR((B3/100)*VLOOKUP($A3,TABELA_TECNICA!$A:$R,14,FALSE),"") -> 0 | P3: =IFERROR((B3/100)*VLOOKUP($A3,TABELA_TECNICA!$A:$R,15,FALSE),"") -> 0 | Q3: =IFERROR((B3/100)*VLOOKUP($A3,TABELA_TECNICA!$A:$R,16,FALSE),"") -> 120
A4: =TABELA_TECNICA!A4 -> Suco de limão | B4: 50 | C4: =IFERROR((B4/100)*VLOOKUP($A4,TABELA_TECNICA!$A:$R,2,FALSE),"") -> 0 | D4: =IFERROR((B4/100)*VLOOKUP($A4,TABELA_TECNICA!$A:$R,3,FALSE),"") -> 3.8 | E4: =IFERROR((B4/100)*VLOOKUP($A4,TABELA_TECNICA!$A:$R,4,FALSE),"") -> 0 | F4: =IFERROR((B4/100)*VLOOKUP($A4,TABELA_TECNICA!$A:$R,5,FALSE),"") -> 0 | G4: =IFERROR((B4/100)*VLOOKUP($A4,TABELA_TECNICA!$A:$R,6,FALSE),"") -> 0.3 | H4: =IFERROR((B4/100)*VLOOKUP($A4,TABELA_TECNICA!$A:$R,7,FALSE),"") -> 0.05 | I4: =IFERROR((B4/100)*VLOOKUP($A4,TABELA_TECNICA!$A:$R,8,FALSE),"") -> 0 | J4: =IFERROR((B4/100)*VLOOKUP($A4,TABELA_TECNICA!$A:$R,9,FALSE),"") -> 0 | K4: =IFERROR((B4/100)*VLOOKUP($A4,TABELA_TECNICA!$A:$R,10,FALSE),"") -> 0 | L4: =IFERROR((B4/100)*VLOOKUP($A4,TABELA_TECNICA!$A:$R,11,FALSE),"") -> 0 | M4: =IFERROR((B4/100)*VLOOKUP($A4,TABELA_TECNICA!$A:$R,12,FALSE),"") -> 0 | N4: =IFERROR((B4/100)*VLOOKUP($A4,TABELA_TECNICA!$A:$R,13,FALSE),"") -> 0 | O4: =IFERROR((B4/100)*VLOOKUP($A4,TABELA_TECNICA!$A:$R,14,FALSE),"") -> 0 | P4: =IFERROR((B4/100)*VLOOKUP($A4,TABELA_TECNICA!$A:$R,15,FALSE),"") -> 0 | Q4: =IFERROR((B4/100)*VLOOKUP($A4,TABELA_TECNICA!$A:$R,16,FALSE),"") -> 0
A5: =TABELA_TECNICA!A5 | C5: =IFERROR((B5/100)*VLOOKUP($A5,TABELA_TECNICA!$A:$R,2,FALSE),"") | D5: =IFERROR((B5/100)*VLOOKUP($A5,TABELA_TECNICA!$A:$R,3,FALSE),"") | E5: =IFERROR((B5/100)*VLOOKUP($A5,TABELA_TECNICA!$A:$R,4,FALSE),"") | F5: =IFERROR((B5/100)*VLOOKUP($A5,TABELA_TECNICA!$A:$R,5,FALSE),"") | G5: =IFERROR((B5/100)*VLOOKUP($A5,TABELA_TECNICA!$A:$R,6,FALSE),"") | H5: =IFERROR((B5/100)*VLOOKUP($A5,TABELA_TECNICA!$A:$R,7,FALSE),"") | I5: =IFERROR((B5/100)*VLOOKUP($A5,TABELA_TECNICA!$A:$R,8,FALSE),"") | J5: =IFERROR((B5/100)*VLOOKUP($A5,TABELA_TECNICA!$A:$R,9,FALSE),"") | K5: =IFERROR((B5/100)*VLOOKUP($A5,TABELA_TECNICA!$A:$R,10,FALSE),"") | L5: =IFERROR((B5/100)*VLOOKUP($A5,TABELA_TECNICA!$A:$R,11,FALSE),"") | M5: =IFERROR((B5/100)*VLOOKUP($A5,TABELA_TECNICA!$A:$R,12,FALSE),"") | N5: =IFERROR((B5/100)*VLOOKUP($A5,TABELA_TECNICA!$A:$R,13,FALSE),"") | O5: =IFERROR((B5/100)*VLOOKUP($A5,TABELA_TECNICA!$A:$R,14,FALSE),"") | P5: =IFERROR((B5/100)*VLOOKUP($A5,TABELA_TECNICA!$A:$R,15,FALSE),"") | Q5: =IFERROR((B5/100)*VLOOKUP($A5,TABELA_TECNICA!$A:$R,16,FALSE),"")
A6: =TABELA_TECNICA!A6 | C6: =IFERROR((B6/100)*VLOOKUP($A6,TABELA_TECNICA!$A:$R,2,FALSE),"") | D6: =IFERROR((B6/100)*VLOOKUP($A6,TABELA_TECNICA!$A:$R,3,FALSE),"") | E6: =IFERROR((B6/100)*VLOOKUP($A6,TABELA_TECNICA!$A:$R,4,FALSE),"") | F6: =IFERROR((B6/100)*VLOOKUP($A6,TABELA_TECNICA!$A:$R,5,FALSE),"") | G6: =IFERROR((B6/100)*VLOOKUP($A6,TABELA_TECNICA!$A:$R,6,FALSE),"") | H6: =IFERROR((B6/100)*VLOOKUP($A6,TABELA_TECNICA!$A:$R,7,FALSE),"") | I6: =IFERROR((B6/100)*VLOOKUP($A6,TABELA_TECNICA!$A:$R,8,FALSE),"") | J6: =IFERROR((B6/100)*VLOOKUP($A6,TABELA_TECNICA!$A:$R,9,FALSE),"") | K6: =IFERROR((B6/100)*VLOOKUP($A6,TABELA_TECNICA!$A:$R,10,FALSE),"") | L6: =IFERROR((B6/100)*VLOOKUP($A6,TABELA_TECNICA!$A:$R,11,FALSE),"") | M6: =IFERROR((B6/100)*VLOOKUP($A6,TABELA_TECNICA!$A:$R,12,FALSE),"") | N6: =IFERROR((B6/100)*VLOOKUP($A6,TABELA_TECNICA!$A:$R,13,FALSE),"") | O6: =IFERROR((B6/100)*VLOOKUP($A6,TABELA_TECNICA!$A:$R,14,FALSE),"") | P6: =IFERROR((B6/100)*VLOOKUP($A6,TABELA_TECNICA!$A:$R,15,FALSE),"") | Q6: =IFERROR((B6/100)*VLOOKUP($A6,TABELA_TECNICA!$A:$R,16,FALSE),"")
A7: =TABELA_TECNICA!A7 | C7: =IFERROR((B7/100)*VLOOKUP($A7,TABELA_TECNICA!$A:$R,2,FALSE),"") | D7: =IFERROR((B7/100)*VLOOKUP($A7,TABELA_TECNICA!$A:$R,3,FALSE),"") | E7: =IFERROR((B7/100)*VLOOKUP($A7,TABELA_TECNICA!$A:$R,4,FALSE),"") | F7: =IFERROR((B7/100)*VLOOKUP($A7,TABELA_TECNICA!$A:$R,5,FALSE),"") | G7: =IFERROR((B7/100)*VLOOKUP($A7,TABELA_TECNICA!$A:$R,6,FALSE),"") | H7: =IFERROR((B7/100)*VLOOKUP($A7,TABELA_TECNICA!$A:$R,7,FALSE),"") | I7: =IFERROR((B7/100)*VLOOKUP($A7,TABELA_TECNICA!$A:$R,8,FALSE),"") | J7: =IFERROR((B7/100)*VLOOKUP($A7,TABELA_TECNICA!$A:$R,9,FALSE),"") | K7: =IFERROR((B7/100)*VLOOKUP($A7,TABELA_TECNICA!$A:$R,10,FALSE),"") | L7: =IFERROR((B7/100)*VLOOKUP($A7,TABELA_TECNICA!$A:$R,11,FALSE),"") | M7: =IFERROR((B7/100)*VLOOKUP($A7,TABELA_TECNICA!$A:$R,12,FALSE),"") | N7: =IFERROR((B7/100)*VLOOKUP($A7,TABELA_TECNICA!$A:$R,13,FALSE),"") | O7: =IFERROR((B7/100)*VLOOKUP($A7,TABELA_TECNICA!$A:$R,14,FALSE),"") | P7: =IFERROR((B7/100)*VLOOKUP($A7,TABELA_TECNICA!$A:$R,15,FALSE),"") | Q7: =IFERROR((B7/100)*VLOOKUP($A7,TABELA_TECNICA!$A:$R,16,FALSE),"")
A8: =TABELA_TECNICA!A8 | C8: =IFERROR((B8/100)*VLOOKUP($A8,TABELA_TECNICA!$A:$R,2,FALSE),"") | D8: =IFERROR((B8/100)*VLOOKUP($A8,TABELA_TECNICA!$A:$R,3,FALSE),"") | E8: =IFERROR((B8/100)*VLOOKUP($A8,TABELA_TECNICA!$A:$R,4,FALSE),"") | F8: =IFERROR((B8/100)*VLOOKUP($A8,TABELA_TECNICA!$A:$R,5,FALSE),"") | G8: =IFERROR((B8/100)*VLOOKUP($A8,TABELA_TECNICA!$A:$R,6,FALSE),"") | H8: =IFERROR((B8/100)*VLOOKUP($A8,TABELA_TECNICA!$A:$R,7,FALSE),"") | I8: =IFERROR((B8/100)*VLOOKUP($A8,TABELA_TECNICA!$A:$R,8,FALSE),"") | J8: =IFERROR((B8/100)*VLOOKUP($A8,TABELA_TECNICA!$A:$R,9,FALSE),"") | K8: =IFERROR((B8/100)*VLOOKUP($A8,TABELA_TECNICA!$A:$R,10,FALSE),"") | L8: =IFERROR((B8/100)*VLOOKUP($A8,TABELA_TECNICA!$A:$R,11,FALSE),"") | M8: =IFERROR((B8/100)*VLOOKUP($A8,TABELA_TECNICA!$A:$R,12,FALSE),"") | N8: =IFERROR((B8/100)*VLOOKUP($A8,TABELA_TECNICA!$A:$R,13,FALSE),"") | O8: =IFERROR((B8/100)*VLOOKUP($A8,TABELA_TECNICA!$A:$R,14,FALSE),"") | P8: =IFERROR((B8/100)*VLOOKUP($A8,TABELA_TECNICA!$A:$R,15,FALSE),"") | Q8: =IFERROR((B8/100)*VLOOKUP($A8,TABELA_TECNICA!$A:$R,16,FALSE),"")
A9: =TABELA_TECNICA!A9 | C9: =IFERROR((B9/100)*VLOOKUP($A9,TABELA_TECNICA!$A:$R,2,FALSE),"") | D9: =IFERROR((B9/100)*VLOOKUP($A9,TABELA_TECNICA!$A:$R,3,FALSE),"") | E9: =IFERROR((B9/100)*VLOOKUP($A9,TABELA_TECNICA!$A:$R,4,FALSE),"") | F9: =IFERROR((B9/100)*VLOOKUP($A9,TABELA_TECNICA!$A:$R,5,FALSE),"") | G9: =IFERROR((B9/100)*VLOOKUP($A9,TABELA_TECNICA!$A:$R,6,FALSE),"") | H9: =IFERROR((B9/100)*VLOOKUP($A9,TABELA_TECNICA!$A:$R,7,FALSE),"") | I9: =IFERROR((B9/100)*VLOOKUP($A9,TABELA_TECNICA!$A:$R,8,FALSE),"") | J9: =IFERROR((B9/100)*VLOOKUP($A9,TABELA_TECNICA!$A:$R,9,FALSE),"") | K9: =IFERROR((B9/100)*VLOOKUP($A9,TABELA_TECNICA!$A:$R,10,FALSE),"") | L9: =IFERROR((B9/100)*VLOOKUP($A9,TABELA_TECNICA!$A:$R,11,FALSE),"") | M9: =IFERROR((B9/100)*VLOOKUP($A9,TABELA_TECNICA!$A:$R,12,FALSE),"") | N9: =IFERROR((B9/100)*VLOOKUP($A9,TABELA_TECNICA!$A:$R,13,FALSE),"") | O9: =IFERROR((B9/100)*VLOOKUP($A9,TABELA_TECNICA!$A:$R,14,FALSE),"") | P9: =IFERROR((B9/100)*VLOOKUP($A9,TABELA_TECNICA!$A:$R,15,FALSE),"") | Q9: =IFERROR((B9/100)*VLOOKUP($A9,TABELA_TECNICA!$A:$R,16,FALSE),"")
A10: =TABELA_TECNICA!A10 | C10: =IFERROR((B10/100)*VLOOKUP($A10,TABELA_TECNICA!$A:$R,2,FALSE),"") | D10: =IFERROR((B10/100)*VLOOKUP($A10,TABELA_TECNICA!$A:$R,3,FALSE),"") | E10: =IFERROR((B10/100)*VLOOKUP($A10,TABELA_TECNICA!$A:$R,4,FALSE),"") | F10: =IFERROR((B10/100)*VLOOKUP($A10,TABELA_TECNICA!$A:$R,5,FALSE),"") | G10: =IFERROR((B10/100)*VLOOKUP($A10,TABELA_TECNICA!$A:$R,6,FALSE),"") | H10: =IFERROR((B10/100)*VLOOKUP($A10,TABELA_TECNICA!$A:$R,7,FALSE),"") | I10: =IFERROR((B10/100)*VLOOKUP($A10,TABELA_TECNICA!$A:$R,8,FALSE),"") | J10: =IFERROR((B10/100)*VLOOKUP($A10,TABELA_TECNICA!$A:$R,9,FALSE),"") | K10: =IFERROR((B10/100)*VLOOKUP($A10,TABELA_TECNICA!$A:$R,10,FALSE),"") | L10: =IFERROR((B10/100)*VLOOKUP($A10,TABELA_TECNICA!$A:$R,11,FALSE),"") | M10: =IFERROR((B10/100)*VLOOKUP($A10,TABELA_TECNICA!$A:$R,12,FALSE),"") | N10: =IFERROR((B10/100)*VLOOKUP($A10,TABELA_TECNICA!$A:$R,13,FALSE),"") | O10: =IFERROR((B10/100)*VLOOKUP($A10,TABELA_TECNICA!$A:$R,14,FALSE),"") | P10: =IFERROR((B10/100)*VLOOKUP($A10,TABELA_TECNICA!$A:$R,15,FALSE),"") | Q10: =IFERROR((B10/100)*VLOOKUP($A10,TABELA_TECNICA!$A:$R,16,FALSE),"")
A11: =TABELA_TECNICA!A11 | C11: =IFERROR((B11/100)*VLOOKUP($A11,TABELA_TECNICA!$A:$R,2,FALSE),"") | D11: =IFERROR((B11/100)*VLOOKUP($A11,TABELA_TECNICA!$A:$R,3,FALSE),"") | E11: =IFERROR((B11/100)*VLOOKUP($A11,TABELA_TECNICA!$A:$R,4,FALSE),"") | F11: =IFERROR((B11/100)*VLOOKUP($A11,TABELA_TECNICA!$A:$R,5,FALSE),"") | G11: =IFERROR((B11/100)*VLOOKUP($A11,TABELA_TECNICA!$A:$R,6,FALSE),"") | H11: =IFERROR((B11/100)*VLOOKUP($A11,TABELA_TECNICA!$A:$R,7,FALSE),"") | I11: =IFERROR((B11/100)*VLOOKUP($A11,TABELA_TECNICA!$A:$R,8,FALSE),"") | J11: =IFERROR((B11/100)*VLOOKUP($A11,TABELA_TECNICA!$A:$R,9,FALSE),"") | K11: =IFERROR((B11/100)*VLOOKUP($A11,TABELA_TECNICA!$A:$R,10,FALSE),"") | L11: =IFERROR((B11/100)*VLOOKUP($A11,TABELA_TECNICA!$A:$R,11,FALSE),"") | M11: =IFERROR((B11/100)*VLOOKUP($A11,TABELA_TECNICA!$A:$R,12,FALSE),"") | N11: =IFERROR((B11/100)*VLOOKUP($A11,TABELA_TECNICA!$A:$R,13,FALSE),"") | O11: =IFERROR((B11/100)*VLOOKUP($A11,TABELA_TECNICA!$A:$R,14,FALSE),"") | P11: =IFERROR((B11/100)*VLOOKUP($A11,TABELA_TECNICA!$A:$R,15,FALSE),"") | Q11: =IFERROR((B11/100)*VLOOKUP($A11,TABELA_TECNICA!$A:$R,16,FALSE),"")
A12: =TABELA_TECNICA!A12 | C12: =IFERROR((B12/100)*VLOOKUP($A12,TABELA_TECNICA!$A:$R,2,FALSE),"") | D12: =IFERROR((B12/100)*VLOOKUP($A12,TABELA_TECNICA!$A:$R,3,FALSE),"") | E12: =IFERROR((B12/100)*VLOOKUP($A12,TABELA_TECNICA!$A:$R,4,FALSE),"") | F12: =IFERROR((B12/100)*VLOOKUP($A12,TABELA_TECNICA!$A:$R,5,FALSE),"") | G12: =IFERROR((B12/100)*VLOOKUP($A12,TABELA_TECNICA!$A:$R,6,FALSE),"") | H12: =IFERROR((B12/100)*VLOOKUP($A12,TABELA_TECNICA!$A:$R,7,FALSE),"") | I12: =IFERROR((B12/100)*VLOOKUP($A12,TABELA_TECNICA!$A:$R,8,FALSE),"") | J12: =IFERROR((B12/100)*VLOOKUP($A12,TABELA_TECNICA!$A:$R,9,FALSE),"") | K12: =IFERROR((B12/100)*VLOOKUP($A12,TABELA_TECNICA!$A:$R,10,FALSE),"") | L12: =IFERROR((B12/100)*VLOOKUP($A12,TABELA_TECNICA!$A:$R,11,FALSE),"") | M12: =IFERROR((B12/100)*VLOOKUP($A12,TABELA_TECNICA!$A:$R,12,FALSE),"") | N12: =IFERROR((B12/100)*VLOOKUP($A12,TABELA_TECNICA!$A:$R,13,FALSE),"") | O12: =IFERROR((B12/100)*VLOOKUP($A12,TABELA_TECNICA!$A:$R,14,FALSE),"") | P12: =IFERROR((B12/100)*VLOOKUP($A12,TABELA_TECNICA!$A:$R,15,FALSE),"") | Q12: =IFERROR((B12/100)*VLOOKUP($A12,TABELA_TECNICA!$A:$R,16,FALSE),"")
A13: =TABELA_TECNICA!A13 | C13: =IFERROR((B13/100)*VLOOKUP($A13,TABELA_TECNICA!$A:$R,2,FALSE),"") | D13: =IFERROR((B13/100)*VLOOKUP($A13,TABELA_TECNICA!$A:$R,3,FALSE),"") | E13: =IFERROR((B13/100)*VLOOKUP($A13,TABELA_TECNICA!$A:$R,4,FALSE),"") | F13: =IFERROR((B13/100)*VLOOKUP($A13,TABELA_TECNICA!$A:$R,5,FALSE),"") | G13: =IFERROR((B13/100)*VLOOKUP($A13,TABELA_TECNICA!$A:$R,6,FALSE),"") | H13: =IFERROR((B13/100)*VLOOKUP($A13,TABELA_TECNICA!$A:$R,7,FALSE),"") | I13: =IFERROR((B13/100)*VLOOKUP($A13,TABELA_TECNICA!$A:$R,8,FALSE),"") | J13: =IFERROR((B13/100)*VLOOKUP($A13,TABELA_TECNICA!$A:$R,9,FALSE),"") | K13: =IFERROR((B13/100)*VLOOKUP($A13,TABELA_TECNICA!$A:$R,10,FALSE),"") | L13: =IFERROR((B13/100)*VLOOKUP($A13,TABELA_TECNICA!$A:$R,11,FALSE),"") | M13: =IFERROR((B13/100)*VLOOKUP($A13,TABELA_TECNICA!$A:$R,12,FALSE),"") | N13: =IFERROR((B13/100)*VLOOKUP($A13,TABELA_TECNICA!$A:$R,13,FALSE),"") | O13: =IFERROR((B13/100)*VLOOKUP($A13,TABELA_TECNICA!$A:$R,14,FALSE),"") | P13: =IFERROR((B13/100)*VLOOKUP($A13,TABELA_TECNICA!$A:$R,15,FALSE),"") | Q13: =IFERROR((B13/100)*VLOOKUP($A13,TABELA_TECNICA!$A:$R,16,FALSE),"")
A14: TOTAL_RECEITA | C14: =SUM(C2:C13) -> 430 | D14: =SUM(D2:D13) -> 1094.9 | E14: =SUM(E2:E13) -> 1043.8 | F14: =SUM(F2:F13) -> 995 | G14: =SUM(G2:G13) -> 17.2 | H14: =SUM(H2:H13) -> 4.95 | I14: =SUM(I2:I13) -> 0.1 | J14: =SUM(J2:J13) -> 0 | ... Q14: =SUM(Q2:Q13) -> 130
A16: Produção | B16: 1680 | C16: Rendimento
A17: Porcao_g | B17: 20 | C17: Produção | D17: 6 | E17: potes
A18: Total de Porcao und | B18: =B16/B17 -> 84 | D18: 280 | E18: g
A19: Valor calorico porção | B19: =(B20*B17)/100 -> 54.749405
A20: Valor calorico 100g | B20: =(B31*4)+(B34*4)+(B35*9)+(B38*2) -> 273.74702
A21: INFORMAÇÃO NUTRICIONAL
A23: NOME DO PRODUTO: ____________________________
A25: Porções por embalagem | B25: =D18/B17 -> 14
A27: Descrição | B27: 100 g | C27: Porção | D27: %VD
A30: Valor energético (kcal) | B30: =B20 -> 273.74702 | C30: =B19 -> 54.749405 | D30: =(C30*100)/B61 -> 2.7374702
A31: Carboidratos (g) | B31: =(D14*100/$B$16) -> 65.172619 | C31: =($B$17*D14)/$B$16 -> 13.034524 | D31: =(C31*100)/B62 -> 4.3448413
A32: Açúcares totais (g) | B32: =(D14*100/$B$16) -> 65.172619 | C32: =($B$17*E14)/$B$16 -> 12.42619
A33: Açúcares adicionados (g) | B33: =(F14*100/$B$16) -> 59.22619 | C33: =($B$17*F14)/$B$16 -> 11.845238 | D33: =(C33*100)/B63 -> 23.690476
A34: Proteínas (g) | B34: =(G14*100/$B$16) -> 1.0238095 | C34: =IF(G14 > 0.5, 0, ($B$17 * G14) / $B$16) -> 0 | D34: =(C34*100)/B65 -> 0
A35: Gorduras totais (g) | B35: =(H14*100/$B$16) -> 0.29464286 | C35: =($B$17*H14)/$B$16 -> 0.058928571 | D35: =(C35*100)/B65 -> 0.090659341
A36: Gorduras saturadas (g) | B36: =(I14*100/$B$16) -> 0.005952381 | C36: =($B$17*I14)/$B$16 -> 0.0011904762 | D36: =(C36*100)/B67 -> 0.05952381
A37: Gorduras trans (g) | B37: =(J14*100/$B$16) -> 0 | C37: =($B$17*J14)/$B$16 -> 0 | D37: =(C37*100)/B67 -> 0
A38: Fibras alimentares (g) | B38: =(P14*100/$B$16) -> 3.1547619 | C38: =($B$17*P14)/$B$16 -> 0.63095238 | D38: =(C38*100)/B73 -> 2.5238095
A39: Sódio (mg) | B39: =(Q14*100/$B$16) -> 7.7380952 | C39: =($B$17*Q14/$B$16) -> 1.547619 | D39: =(C39*100)/B74 -> 0.077380952
A40: *%VD baseada em uma dieta de 2.000 kcal. Informação para fins de rotulagem. Verifique legislações vigentes (IN 75/2020, RDC 429/2020).
A55: REFERENCIA
A58: IN 75/2020
A60: Constituintes | B60: VDR (unidade)
A61: Valor energético | B61: 2.000 | C61: kcal
A62: Carboidratos | B62: 300 | C62: g
A63: Açúcares adicionados | B63: 50 | C63: g
...
